Workbook

Sheet Resumen_P&G
A1: Escriba Comuna | H1: Región Metropolitana De Santiago
A2: Santiago | B2: 16 Rollos | C2: 24 Rollos
B3: 16 Rollos Promedio | E3: 24 Rollos Promedio
A4: MODELO1 | B4: YTD | C4: PROM YEAR | E4: YTD | F4: PROM YEAR
A5: Clientes Iniciales | B5: =+'P&G_Agente_Inmobiliario'!O7 -> 986.15266 | C5: =+B5/12 -> 82.179389 | E5: =+'P&G_Agente_Inmobiliario'!#REF! -> #REF! | F5: =+E5/12 -> #REF!
A6: Confort por Paquete | B6: =+'P&G_Agente_Inmobiliario'!O13 -> 176 | C6: =+B6/12 -> 14.666667 | E6: =+'P&G_Agente_Inmobiliario'!#REF! -> #REF! | F6: =+E6/12 -> #REF!
A7: Cantidad de paquetes | B7: =+'P&G_Agente_Inmobiliario'!O9 -> 5130.9439 | C7: =+B7/12 -> 427.57866 | E7: =+'P&G_Agente_Inmobiliario'!#REF! -> #REF! | F7: =+E7/12 -> #REF!
A8: Costo por paquete | B8: =+'P&G_Agente_Inmobiliario'!#REF! -> #REF! | E8: =+'P&G_Agente_Inmobiliario'!#REF! -> #REF!
A9: Venta por paquete | B9: =+'P&G_Agente_Inmobiliario'!O11 -> 1.4879737e+08 | E9: =+'P&G_Agente_Inmobiliario'!#REF! -> #REF!
A10: Costo por unidad | B10: =+'P&G_Agente_Inmobiliario'!#REF! -> #REF! | E10: =+'P&G_Agente_Inmobiliario'!#REF! -> #REF! | F10: =+E10 -> #REF!
A11: Venta por unidad | B11: =+'P&G_Agente_Inmobiliario'!O12 -> 44367574 | E11: =+'P&G_Agente_Inmobiliario'!#REF! -> #REF! | F11: =+E11 -> #REF!
A12: Tasa de Clientes | B12: =+'P&G_Agente_Inmobiliario'!O14 -> 0.07 | E12: =+'P&G_Agente_Inmobiliario'!#REF! -> #REF!
A13: Churn Clientes | B13: =+'P&G_Agente_Inmobiliario'!O15 -> 0.0625 | E13: =+'P&G_Agente_Inmobiliario'!#REF! -> #REF!
A14: Paquetes por cliente | B14: =+'P&G_Agente_Inmobiliario'!#REF! -> #REF! | E14: =+'P&G_Agente_Inmobiliario'!#REF! -> #REF!
A15: Clientes Finales | B15: =+'P&G_Agente_Inmobiliario'!O16 -> 6195.9877 | E15: =+'P&G_Agente_Inmobiliario'!#REF! -> #REF!
A16: Ingresos | B16: =+'P&G_Agente_Inmobiliario'!O17 -> 1.9316495e+08 | C16: =+B16/12 -> 16097079 | E16: =+'P&G_Agente_Inmobiliario'!#REF! -> #REF! | F16: =+E16/12 -> #REF!
A18: Costos Productos | B18: =+'P&G_Agente_Inmobiliario'!O19 -> -28974742 | C18: =+B18/12 -> -2414561.8 | E18: =+'P&G_Agente_Inmobiliario'!#REF! -> #REF! | F18: =+E18/12 -> #REF!
A19: Costos Directos | B19: =+'P&G_Agente_Inmobiliario'!O20 -> -57949484 | C19: =+B19/12 -> -4829123.6 | E19: =+'P&G_Agente_Inmobiliario'!#REF! -> #REF! | F19: =+E19/12 -> #REF!
A20: Costos MKT | B20: =+'P&G_Agente_Inmobiliario'!O21 -> -28974742 | C20: =+B20/12 -> -2414561.8 | E20: =+'P&G_Agente_Inmobiliario'!#REF! -> #REF! | F20: =+E20/12 -> #REF!
A21: Costos Despachos | B21: =+'P&G_Agente_Inmobiliario'!O23 -> 0 | C21: =+B21/12 -> 0 | E21: =+'P&G_Agente_Inmobiliario'!#REF! -> #REF! | F21: =+E21/12 -> #REF!
A22: TT Costos | B22: =+'P&G_Agente_Inmobiliario'!O24 -> -1.2429897e+08 | C22: =+B22/12 -> -10358247 | E22: =+'P&G_Agente_Inmobiliario'!#REF! -> #REF! | F22: =+E22/12 -> #REF!
A23: Costos Acumulados | B23: =+'P&G_Agente_Inmobiliario'!O25 -> 0 | E23: =+'P&G_Agente_Inmobiliario'!#REF! -> #REF!
A25: MB $ | B25: =+'P&G_Agente_Inmobiliario'!O27 -> 68865979 | C25: =+B25/12 -> 5738831.6 | E25: =+'P&G_Agente_Inmobiliario'!#REF! -> #REF! | F25: =+E25/12 -> #REF!
A26: MB % | B26: =+'P&G_Agente_Inmobiliario'!O28 -> 0.35651385 | C26: =+C25/C16 -> 0.35651385 | E26: =+'P&G_Agente_Inmobiliario'!#REF! -> #REF! | F26: =+F25/F16 -> #REF!
A27: MB Acumulado $ | B27: =+'P&G_Agente_Inmobiliario'!O29 -> 0 | E27: =+'P&G_Agente_Inmobiliario'!#REF! -> #REF!
A28: MB Acumulado % | B28: =+'P&G_Agente_Inmobiliario'!O30 -> 0 | E28: =+'P&G_Agente_Inmobiliario'!#REF! -> #REF!

Sheet P&G_Agente_Inmobiliario
I1: Dólar
I2: 950
A3: Escenario Moderarado Gestión Inmobiliaria
A4: MODELO1 | B4: Mes 0 | C4: Mes 1 | D4: Mes 2 | E4: Mes 3 | F4: Mes 4 | G4: Mes 5 | H4: Mes 6 | I4: Mes 7 | J4: Mes 8 | K4: Mes 9 | L4: Mes 10 | M4: Mes 11 | N4: Mes 12 | O4: YTD | P4: PROM YEAR
A5: Parque | B5: 8000 | C5: =+B5 -> 8000 | D5: =+C5-C16 -> 7961.2 | E5: =+D5-D16 -> 7868.3435 | F5: =+E5-E16 -> 7706.7963 | G5: =+F5-F16 -> 7465.6209 | H5: =+G5-G16 -> 7135.754 | I5: =+H5-H16 -> 6706.9855 | J5: =+I5-I16 -> 6162.6072 | K5: =+J5-J16 -> 5511.3693 | ... N5: =+M5-M16 -> 2881.4726 | O5: =+SUM(C5:N5) -> 76021.637 | P5: =+O5/12 -> 6335.1364
A6: %Penetración | B6: 0.01 | C6: 0.005 | D6: 0.007 | E6: 0.009 | F6: 0.01 | G6: 0.012 | H6: 0.014 | I6: 0.015 | J6: 0.017 | K6: 0.019 | L6: 0.021 | M6: 0.025 | N6: 0.03 | O6: =+SUM(C6:N6) -> 0.184 | P6: =+O6/12 -> 0.015333333
A7: Clientes Iniciales | B7: =+B5*B6 -> 80 | D7: =+D5*D6 -> 55.7284 | E7: =+E5*E6 -> 70.815091 | F7: =+F5*F6 -> 77.067963 | G7: =+G5*G6 -> 89.587451 | H7: =+H5*H6 -> 99.900556 | I7: =+I5*I6 -> 100.60478 | J7: =+J5*J6 -> 104.76432 | K7: =+K5*K6 -> 104.71602 | ... N7: =+N5*N6 -> 86.444177 | O7: =+SUM(C7:N7) -> 986.15266 | P7: =+O7/12 -> 82.179389
A8: Clientes Acumulados | C8: =+C5*C6 -> 40 | D8: =+D7+C8 -> 95.7284 | E8: =+E7+D8 -> 166.54349 | F8: =+F7+E8 -> 243.61145 | G8: =+G7+F8 -> 333.1989 | H8: =+H7+G8 -> 433.09946 | I8: =+I7+H8 -> 533.70424 | J8: =+J7+I8 -> 638.46857 | K8: =+K7+J8 -> 743.18458 | ... N8: =+N7+M8 -> 1026.1527
A9: Q Planes 30 USD | B9: 0.85 | C9: =+$B9*C$8 -> 34 | D9: =+$B9*D$8 -> 81.36914 | E9: =+$B9*E$8 -> 141.56197 | F9: =+$B9*F$8 -> 207.06974 | G9: =+$B9*G$8 -> 283.21907 | H9: =+$B9*H$8 -> 368.13454 | I9: =+$B9*I$8 -> 453.64861 | J9: =+$B9*J$8 -> 542.69828 | ... N9: =+$B9*N$8 -> 872.22976 | O9: =+SUM(C9:N9) -> 5130.9439 | P9: =+O9/12 -> 427.57866
A10: Q Planes 50 USD | B10: 0.15 | C10: =+$B10*C$8 -> 6 | D10: =+$B10*D$8 -> 14.35926 | E10: =+$B10*E$8 -> 24.981524 | F10: =+$B10*F$8 -> 36.541718 | G10: =+$B10*G$8 -> 49.979836 | H10: =+$B10*H$8 -> 64.964919 | I10: =+$B10*I$8 -> 80.055637 | J10: =+$B10*J$8 -> 95.770285 | ... N10: =+$B10*N$8 -> 153.9229
A11: Venta Plan 30 USD | B11: 29000 | C11: =+$B11*C$9 -> 986000 | D11: =+$B11*D$9 -> 2359705.1 | E11: =+$B11*E$9 -> 4105297.1 | F11: =+$B11*F$9 -> 6005022.3 | G11: =+$B11*G$9 -> 8213353 | H11: =+$B11*H$9 -> 10675902 | I11: =+$B11*I$9 -> 13155810 | J11: =+$B11*J$9 -> 15738250 | ... N11: =+$B11*N$9 -> 25294663 | O11: =+SUM(C11:N11) -> 1.4879737e+08 | P11: =+O11/12 -> 12399781
A12: Venta Plan 50 USD | B12: 49000 | C12: =+$B12*C$10 -> 294000 | D12: =+$B12*D$10 -> 703603.74 | E12: =+$B12*E$10 -> 1224094.7 | F12: =+$B12*F$10 -> 1790544.2 | G12: =+$B12*G$10 -> 2449012 | H12: =+$B12*H$10 -> 3183281 | I12: =+$B12*I$10 -> 3922726.2 | J12: =+$B12*J$10 -> 4692744 | ... N12: =+$B12*N$10 -> 7542222.1 | O12: =+SUM(C12:N12) -> 44367574 | P12: =+O12/12 -> 3697297.8
A13: Confort por Paquete | D13: 16 | E13: 16 | F13: 16 | G13: 16 | H13: 16 | I13: 16 | J13: 16 | K13: 16 | L13: 16 | M13: 16 | N13: 16 | O13: =+SUM(C13:N13) -> 176 | P13: =+O13/12 -> 14.666667
A14: Tasa de Clientes | B14: 0 | C14: 0.07 | D14: 0.07 | E14: 0.07 | F14: 0.07 | G14: 0.07 | H14: 0.07 | I14: 0.07 | J14: 0.07 | K14: 0.07 | L14: 0.07 | M14: 0.07 | N14: 0.07 | O14: =+AVERAGE(C14:N14) -> 0.07 | P14: =+O14 -> 0.07
A15: Churn Clientes | B15: 0 | C15: 0.1 | D15: 0.1 | E15: 0.1 | F15: 0.08 | G15: 0.08 | H15: 0.08 | I15: 0.05 | J15: 0.05 | K15: 0.05 | L15: 0.02 | M15: 0.02 | N15: 0.02 | O15: =+AVERAGE(C15:N15) -> 0.0625 | P15: =+O15 -> 0.0625
A16: Clientes Finales | B16: =(B8+((B8*B14)-(B8*B15))) -> 0 | C16: =(C8+((C8*C14)-(C8*C15))) -> 38.8 | D16: =(D8+((D8*D14)-(D8*D15))) -> 92.856548 | E16: =(E8+((E8*E14)-(E8*E15))) -> 161.54719 | F16: =(F8+((F8*F14)-(F8*F15))) -> 241.17534 | G16: =(G8+((G8*G14)-(G8*G15))) -> 329.86692 | H16: =(H8+((H8*H14)-(H8*H15))) -> 428.76847 | I16: =(I8+((I8*I14)-(I8*I15))) -> 544.37833 | ... N16: =(N8+((N8*N14)-(N8*N15))) -> 1077.4603 | O16: =+SUM(C16:N16) -> 6195.9877 | P16: =+O16/12 -> 516.33231
A17: Ingresos | C17: =+C11+C12 -> 1280000 | D17: =+D11+D12 -> 3063308.8 | E17: =+E11+E12 -> 5329391.7 | F17: =+F11+F12 -> 7795566.5 | G17: =+G11+G12 -> 10662365 | H17: =+H11+H12 -> 13859183 | I17: =+I11+I12 -> 17078536 | J17: =+J11+J12 -> 20430994 | ... N17: =+N11+N12 -> 32836885 | O17: =+SUM(B17:N17) -> 1.9316495e+08 | P17: =+O17/12 -> 16097079
A19: Costos Productos | B19: 0.15 | C19: =+$B19*C$17*-1 -> -192000 | D19: =+$B19*D$17*-1 -> -459496.32 | E19: =+$B19*E$17*-1 -> -799408.76 | F19: =+$B19*F$17*-1 -> -1169335 | G19: =+$B19*G$17*-1 -> -1599354.7 | H19: =+$B19*H$17*-1 -> -2078877.4 | I19: =+$B19*I$17*-1 -> -2561780.4 | J19: =+$B19*J$17*-1 -> -3064649.1 | ... N19: =+$B19*N$17*-1 -> -4925532.8 | O19: =+SUM(B19:N19) -> -28974742 | P19: =+O19/12 -> -2414561.8
A20: Costos Directos | B20: 0.3 | C20: =+$B20*C$17*-1 -> -384000 | D20: =+$B20*D$17*-1 -> -918992.64 | E20: =+$B20*E$17*-1 -> -1598817.5 | F20: =+$B20*F$17*-1 -> -2338670 | G20: =+$B20*G$17*-1 -> -3198709.5 | H20: =+$B20*H$17*-1 -> -4157754.8 | I20: =+$B20*I$17*-1 -> -5123560.7 | J20: =+$B20*J$17*-1 -> -6129298.2 | ... N20: =+$B20*N$17*-1 -> -9851065.6 | O20: =+SUM(B20:N20) -> -57949484 | P20: =+O20/12 -> -4829123.6
A21: Costos MKT | B21: 0.15 | C21: =+$B21*C$17*-1 -> -192000 | D21: =+$B21*D$17*-1 -> -459496.32 | E21: =+$B21*E$17*-1 -> -799408.76 | F21: =+$B21*F$17*-1 -> -1169335 | G21: =+$B21*G$17*-1 -> -1599354.7 | H21: =+$B21*H$17*-1 -> -2078877.4 | I21: =+$B21*I$17*-1 -> -2561780.4 | J21: =+$B21*J$17*-1 -> -3064649.1 | ... N21: =+$B21*N$17*-1 -> -4925532.8 | O21: =+SUM(B21:N21) -> -28974742 | P21: =+O21/12 -> -2414561.8
A22: Costo Desarrollo | C22: -700000 | D22: -700000 | E22: -700000 | F22: -700000 | G22: -700000 | H22: -700000 | I22: -700000 | J22: -700000 | K22: -700000 | L22: -700000 | M22: -700000 | N22: -700000 | O22: =+SUM(B22:N22) -> -8400000 | P22: =+O22/12 -> -700000
A23: Costos X | C23: =+$B23*C$17*-1 -> 0 | D23: =+$B23*D$17*-1 -> 0 | E23: =+$B23*E$17*-1 -> 0 | F23: =+$B23*F$17*-1 -> 0 | G23: =+$B23*G$17*-1 -> 0 | H23: =+$B23*H$17*-1 -> 0 | I23: =+$B23*I$17*-1 -> 0 | J23: =+$B23*J$17*-1 -> 0 | ... N23: =+$B23*N$17*-1 -> 0 | O23: =+SUM(B23:N23) -> 0 | P23: =+O23/12 -> 0
A24: TT Costos | B24: =B19+B20+B21+B23 -> 0.6 | C24: =C19+C20+C21+C23+C22 -> -1468000 | D24: =D19+D20+D21+D23+D22 -> -2537985.3 | E24: =E19+E20+E21+E23+E22 -> -3897635 | F24: =F19+F20+F21+F23+F22 -> -5377339.9 | G24: =G19+G20+G21+G23+G22 -> -7097419 | H24: =H19+H20+H21+H23+H22 -> -9015509.7 | I24: =I19+I20+I21+I23+I22 -> -10947121 | J24: =J19+J20+J21+J23+J22 -> -12958596 | ... N24: =N19+N20+N21+N23+N22 -> -20402131 | O24: =+SUM(B24:N24) -> -1.2429897e+08 | P24: =+O24/12 -> -10358247
A25: Costos Acumulados | B25: =+B24 -> 0.6 | C25: =+B25+C24 -> -1467999.4 | D25: =+C25+D24 -> -4005984.7 | E25: =+D25+E24 -> -7903619.7 | F25: =+E25+F24 -> -13280960 | G25: =+F25+G24 -> -20378379 | H25: =+G25+H24 -> -29393888 | I25: =+H25+I24 -> -40341010 | J25: =+I25+J24 -> -53299606 | ... N25: =+M25+N24 -> -1.2429897e+08
A27: MB $ | C27: =+C17+C24 -> -188000 | D27: =+D17+D24 -> 525323.52 | E27: =+E17+E24 -> 1431756.7 | F27: =+F17+F24 -> 2418226.6 | G27: =+G17+G24 -> 3564946 | H27: =+H17+H24 -> 4843673.1 | I27: =+I17+I24 -> 6131414.3 | J27: =+J17+J24 -> 7472397.7 | ... O27: =+O17+O24 -> 68865979 | P27: =+O27/12 -> 5738831.6
A28: MB % | C28: =+C27/C17 -> -0.146875 | D28: =+D27/D17 -> 0.17148892 | E28: =+E27/E17 -> 0.26865293 | F28: =+F27/F17 -> 0.31020537 | G28: =+G27/G17 -> 0.33434852 | H28: =+H27/H17 -> 0.34949197 | I28: =+I27/I17 -> 0.35901288 | J28: =+J27/J17 -> 0.36573833 | ... P28: =+P27/P17 -> 0.35651385
A29: MB Acumulado $ | C29: =+SUM($B$17:C17)+C25 -> -187999.4 | D29: =+SUM($B$17:D17)+D25 -> 337324.12 | E29: =+SUM($B$17:E17)+E25 -> 1769080.8 | F29: =+SUM($B$17:F17)+F25 -> 4187307.4 | G29: =+SUM($B$17:G17)+G25 -> 7752253.4 | H29: =+SUM($B$17:H17)+H25 -> 12595926 | I29: =+SUM($B$17:I17)+I25 -> 18727341 | J29: =+SUM($B$17:J17)+J25 -> 26199738 | ... N29: =+SUM($B$17:N17)+N25 -> 68865979
A30: MB Acumulado % | C30: =+C29/+SUM($B$17:C17) -> -0.14687453 | D30: =+D29/+SUM($B$17:D17) -> 0.07766524 | E30: =+E29/+SUM($B$17:E17) -> 0.1828942 | F30: =+F29/+SUM($B$17:F17) -> 0.23970938 | G30: =+G29/+SUM($B$17:G17) -> 0.27558049 | H30: =+H29/+SUM($B$17:H17) -> 0.29997576 | I30: =+I29/+SUM($B$17:I17) -> 0.31704526 | J30: =+J29/+SUM($B$17:J17) -> 0.32955918 | ... N30: =+N29/+SUM($B$17:N17) -> 0.35651385

Sheet Hoja1
C1: VALORES EN UF | F1: VALORES EN CLP | I1: VALORES EN CLP x PUBLICACION | N1: Valor UF | O1: 39200
A2: Nombre del plan | B2: Cupo de publicaciones | C2: Costo Neto | D2: Iva | E2: Costo Bruto | F2: Costo Neto | G2: Iva | H2: Costo Bruto | I2: Costo Neto | J2: Iva | K2: Costo Bruto
A3: 5 Publicaciones Plata | B3: 5 | C3: 1 | D3: =+C3*19% -> 0.19 | E3: =+C3+D3 -> 1.19 | F3: =+C3*$O$1 -> 39200 | G3: =+F3*19% -> 7448 | H3: =+F3+G3 -> 46648 | I3: =+F3/B3 -> 7840 | J3: =+I3*19% -> 1489.6 | K3: =+I3+J3 -> 9329.6
A4: 10 Publicaciones Plata | B4: 10 | C4: 1.2 | D4: =+C4*19% -> 0.228 | E4: =+C4+D4 -> 1.428 | F4: =+C4*$O$1 -> 47040 | G4: =+F4*19% -> 8937.6 | H4: =+F4+G4 -> 55977.6 | I4: =+F4/B4 -> 4704 | J4: =+I4*19% -> 893.76 | K4: =+I4+J4 -> 5597.76
A5: 20 Publicaciones Plata | B5: 20 | C5: 1.9 | D5: =+C5*19% -> 0.361 | E5: =+C5+D5 -> 2.261 | F5: =+C5*$O$1 -> 74480 | G5: =+F5*19% -> 14151.2 | H5: =+F5+G5 -> 88631.2 | I5: =+F5/B5 -> 3724 | J5: =+I5*19% -> 707.56 | K5: =+I5+J5 -> 4431.56
A6: 30 Publicaciones Plata | B6: 30 | C6: 2 | D6: =+C6*19% -> 0.38 | E6: =+C6+D6 -> 2.38 | F6: =+C6*$O$1 -> 78400 | G6: =+F6*19% -> 14896 | H6: =+F6+G6 -> 93296 | I6: =+F6/B6 -> 2613.3333 | J6: =+I6*19% -> 496.53333 | K6: =+I6+J6 -> 3109.8667
A7: 50 Publicaciones Plata | B7: 50 | C7: 2.8 | D7: =+C7*19% -> 0.532 | E7: =+C7+D7 -> 3.332 | F7: =+C7*$O$1 -> 109760 | G7: =+F7*19% -> 20854.4 | H7: =+F7+G7 -> 130614.4 | I7: =+F7/B7 -> 2195.2 | J7: =+I7*19% -> 417.088 | K7: =+I7+J7 -> 2612.288
A8: 75 Publicaciones Plata | B8: 75 | C8: 2.9 | D8: =+C8*19% -> 0.551 | E8: =+C8+D8 -> 3.451 | F8: =+C8*$O$1 -> 113680 | G8: =+F8*19% -> 21599.2 | H8: =+F8+G8 -> 135279.2 | I8: =+F8/B8 -> 1515.7333 | J8: =+I8*19% -> 287.98933 | K8: =+I8+J8 -> 1803.7227
A9: 100 Publicaciones Plata | B9: 100 | C9: 3 | D9: =+C9*19% -> 0.57 | E9: =+C9+D9 -> 3.57 | F9: =+C9*$O$1 -> 117600 | G9: =+F9*19% -> 22344 | H9: =+F9+G9 -> 139944 | I9: =+F9/B9 -> 1176 | J9: =+I9*19% -> 223.44 | K9: =+I9+J9 -> 1399.44
A10: 150 Publicaciones Plata | B10: 150 | C10: 4 | D10: =+C10*19% -> 0.76 | E10: =+C10+D10 -> 4.76 | F10: =+C10*$O$1 -> 156800 | G10: =+F10*19% -> 29792 | H10: =+F10+G10 -> 186592 | I10: =+F10/B10 -> 1045.3333 | J10: =+I10*19% -> 198.61333 | K10: =+I10+J10 -> 1243.9467
A11: 200 Publicaciones Plata | B11: 200 | C11: 5 | D11: =+C11*19% -> 0.95 | E11: =+C11+D11 -> 5.95 | F11: =+C11*$O$1 -> 196000 | G11: =+F11*19% -> 37240 | H11: =+F11+G11 -> 233240 | I11: =+F11/B11 -> 980 | J11: =+I11*19% -> 186.2 | K11: =+I11+J11 -> 1166.2
A12: 350 Publicaciones Plata | B12: 350 | C12: 8.8 | D12: =+C12*19% -> 1.672 | E12: =+C12+D12 -> 10.472 | F12: =+C12*$O$1 -> 344960 | G12: =+F12*19% -> 65542.4 | H12: =+F12+G12 -> 410502.4 | I12: =+F12/B12 -> 985.6 | J12: =+I12*19% -> 187.264 | K12: =+I12+J12 -> 1172.864
A13: 500 Publicaciones Plata | B13: 500 | C13: 12.5 | D13: =+C13*19% -> 2.375 | E13: =+C13+D13 -> 14.875 | F13: =+C13*$O$1 -> 490000 | G13: =+F13*19% -> 93100 | H13: =+F13+G13 -> 583100 | I13: =+F13/B13 -> 980 | J13: =+I13*19% -> 186.2 | K13: =+I13+J13 -> 1166.2
A14: 750 Publicaciones Plata | B14: 750 | C14: 18.8 | D14: =+C14*19% -> 3.572 | E14: =+C14+D14 -> 22.372 | F14: =+C14*$O$1 -> 736960 | G14: =+F14*19% -> 140022.4 | H14: =+F14+G14 -> 876982.4 | I14: =+F14/B14 -> 982.61333 | J14: =+I14*19% -> 186.69653 | K14: =+I14+J14 -> 1169.3099
A15: 1.000 Publicaciones Plata | B15: 1000 | C15: 25 | D15: =+C15*19% -> 4.75 | E15: =+C15+D15 -> 29.75 | F15: =+C15*$O$1 -> 980000 | G15: =+F15*19% -> 186200 | H15: =+F15+G15 -> 1166200 | I15: =+F15/B15 -> 980 | J15: =+I15*19% -> 186.2 | K15: =+I15+J15 -> 1166.2
A16: 1.500 Publicaciones Plata | B16: 1500 | C16: 43.5 | D16: =+C16*19% -> 8.265 | E16: =+C16+D16 -> 51.765 | F16: =+C16*$O$1 -> 1705200 | G16: =+F16*19% -> 323988 | H16: =+F16+G16 -> 2029188 | I16: =+F16/B16 -> 1136.8 | J16: =+I16*19% -> 215.992 | K16: =+I16+J16 -> 1352.792 | L16: =+$K$15*B16 -> 1749300 | M16: =+H16-L16 -> 279888
A17: 2.000 Publicaciones Plata | B17: 2000 | C17: 58 | D17: =+C17*19% -> 11.02 | E17: =+C17+D17 -> 69.02 | F17: =+C17*$O$1 -> 2273600 | G17: =+F17*19% -> 431984 | H17: =+F17+G17 -> 2705584 | I17: =+F17/B17 -> 1136.8 | J17: =+I17*19% -> 215.992 | K17: =+I17+J17 -> 1352.792 | L17: =+$K$15*B17 -> 2332400 | M17: =+H17-L17 -> 373184
A18: 2.500 Publicaciones Plata | B18: 2500 | C18: 72.5 | D18: =+C18*19% -> 13.775 | E18: =+C18+D18 -> 86.275 | F18: =+C18*$O$1 -> 2842000 | G18: =+F18*19% -> 539980 | H18: =+F18+G18 -> 3381980 | I18: =+F18/B18 -> 1136.8 | J18: =+I18*19% -> 215.992 | K18: =+I18+J18 -> 1352.792 | L18: =+$K$15*B18 -> 2915500 | M18: =+H18-L18 -> 466480
A19: 3.000 Publicaciones Plata | B19: 3000 | C19: 87 | D19: =+C19*19% -> 16.53 | E19: =+C19+D19 -> 103.53 | F19: =+C19*$O$1 -> 3410400 | G19: =+F19*19% -> 647976 | H19: =+F19+G19 -> 4058376 | I19: =+F19/B19 -> 1136.8 | J19: =+I19*19% -> 215.992 | K19: =+I19+J19 -> 1352.792 | L19: =+$K$15*B19 -> 3498600 | M19: =+H19-L19 -> 559776
A20: 4.000 Publicaciones Plata | B20: 4000 | C20: 116 | D20: =+C20*19% -> 22.04 | E20: =+C20+D20 -> 138.04 | F20: =+C20*$O$1 -> 4547200 | G20: =+F20*19% -> 863968 | H20: =+F20+G20 -> 5411168 | I20: =+F20/B20 -> 1136.8 | J20: =+I20*19% -> 215.992 | K20: =+I20+J20 -> 1352.792 | L20: =+$K$15*B20 -> 4664800 | M20: =+H20-L20 -> 746368
A21: 5.000 Publicaciones Plata | B21: 5000 | C21: 145 | D21: =+C21*19% -> 27.55 | E21: =+C21+D21 -> 172.55 | F21: =+C21*$O$1 -> 5684000 | G21: =+F21*19% -> 1079960 | H21: =+F21+G21 -> 6763960 | I21: =+F21/B21 -> 1136.8 | J21: =+I21*19% -> 215.992 | K21: =+I21+J21 -> 1352.792 | L21: =+$K$15*B21 -> 5831000 | M21: =+H21-L21 -> 932960
A22: 6.000 Publicaciones Plata | B22: 6000 | C22: 174 | D22: =+C22*19% -> 33.06 | E22: =+C22+D22 -> 207.06 | F22: =+C22*$O$1 -> 6820800 | G22: =+F22*19% -> 1295952 | H22: =+F22+G22 -> 8116752 | I22: =+F22/B22 -> 1136.8 | J22: =+I22*19% -> 215.992 | K22: =+I22+J22 -> 1352.792 | L22: =+$K$15*B22 -> 6997200 | M22: =+H22-L22 -> 1119552
A23: 7.000 Publicaciones Plata | B23: 7000 | C23: 203 | D23: =+C23*19% -> 38.57 | E23: =+C23+D23 -> 241.57 | F23: =+C23*$O$1 -> 7957600 | G23: =+F23*19% -> 1511944 | H23: =+F23+G23 -> 9469544 | I23: =+F23/B23 -> 1136.8 | J23: =+I23*19% -> 215.992 | K23: =+I23+J23 -> 1352.792 | L23: =+$K$15*B23 -> 8163400 | M23: =+H23-L23 -> 1306144
A24: 8.000 Publicaciones Plata | B24: 8000 | C24: 232 | D24: =+C24*19% -> 44.08 | E24: =+C24+D24 -> 276.08 | F24: =+C24*$O$1 -> 9094400 | G24: =+F24*19% -> 1727936 | H24: =+F24+G24 -> 10822336 | I24: =+F24/B24 -> 1136.8 | J24: =+I24*19% -> 215.992 | K24: =+I24+J24 -> 1352.792 | L24: =+$K$15*B24 -> 9329600 | M24: =+H24-L24 -> 1492736
A25: 9.000 Publicaciones Plata | B25: 9000 | C25: 261 | D25: =+C25*19% -> 49.59 | E25: =+C25+D25 -> 310.59 | F25: =+C25*$O$1 -> 10231200 | G25: =+F25*19% -> 1943928 | H25: =+F25+G25 -> 12175128 | I25: =+F25/B25 -> 1136.8 | J25: =+I25*19% -> 215.992 | K25: =+I25+J25 -> 1352.792 | L25: =+$K$15*B25 -> 10495800 | M25: =+H25-L25 -> 1679328
A26: 10.000 Publicaciones Plata | B26: 10000 | C26: 290 | D26: =+C26*19% -> 55.1 | E26: =+C26+D26 -> 345.1 | F26: =+C26*$O$1 -> 11368000 | G26: =+F26*19% -> 2159920 | H26: =+F26+G26 -> 13527920 | I26: =+F26/B26 -> 1136.8 | J26: =+I26*19% -> 215.992 | K26: =+I26+J26 -> 1352.792 | L26: =+$K$15*B26 -> 11662000 | M26: =+H26-L26 -> 1865920
A27: 12.000 Publicaciones Plata | B27: 12000 | C27: 348 | D27: =+C27*19% -> 66.12 | E27: =+C27+D27 -> 414.12 | F27: =+C27*$O$1 -> 13641600 | G27: =+F27*19% -> 2591904 | H27: =+F27+G27 -> 16233504 | I27: =+F27/B27 -> 1136.8 | J27: =+I27*19% -> 215.992 | K27: =+I27+J27 -> 1352.792 | L27: =+$K$15*B27 -> 13994400 | M27: =+H27-L27 -> 2239104
... A33: 24.000 Publicaciones Plata | B33: 24000 | C33: 696 | D33: =+C33*19% -> 132.24 | E33: =+C33+D33 -> 828.24 | F33: =+C33*$O$1 -> 27283200 | G33: =+F33*19% -> 5183808 | H33: =+F33+G33 -> 32467008 | I33: =+F33/B33 -> 1136.8 | J33: =+I33*19% -> 215.992 | K33: =+I33+J33 -> 1352.792 | L33: =+$K$15*B33 -> 27988800 | M33: =+H33-L33 -> 4478208

Sheet Hoja3
A1: card-title | B1: fecha_publicacion 2 | C1: wrap_imagen_logo src | D1: wrap_text_rango_precio | E1: wrap_servicio src | F1: wrap_score | G1: numero_propiedades_en_venta | H1: Tramos_Prom_Propiedades
A2: Estudiodos | B2: 2024 | C2: https://http2.mlstatic.com/storage/vis-accounts/1854717500_vip-85ad2a15-b46d-4e1f-baac-fa9f979382c1.jpg | D2: UF 6.000 a 34.600 | E2: https://www.portalinmobiliario.com/static_assets/landing/campana/corredores/img/verde.svg | F2: 1 | G2: 6 | H2: =+IF(G2>=100,"7.Mayor a 100 P",+IF(G2>=70,"6.Mayor a 70 P",+IF(G2>=40,"5.Mayor a 40 P",+IF(G2>=20,"4.Mayor a 20 P",+IF(G2>=10,"3.Mayor a 10 P",+IF(G2<10,"2.Menor a 10 P",+IF(G2=0,"1.Sin Propiedades","Revsar"))))))) -> 2.Menor a 10 P
A3: Portfolio Propiedades | B3: 2022 | C3: https://www.portalinmobiliario.com/static_assets/landing/campana/corredores/img/casa_foto.jpg | D3: UF 1.338 a 17.990 | E3: https://www.portalinmobiliario.com/static_assets/landing/campana/corredores/img/verde.svg | F3: 1 | G3: 6 | H3: =+IF(G3>=100,"7.Mayor a 100 P",+IF(G3>=70,"6.Mayor a 70 P",+IF(G3>=40,"5.Mayor a 40 P",+IF(G3>=20,"4.Mayor a 20 P",+IF(G3>=10,"3.Mayor a 10 P",+IF(G3<10,"2.Menor a 10 P",+IF(G3=0,"1.Sin Propiedades","Revsar"))))))) -> 2.Menor a 10 P
A4: Schmidt Propiedades | B4: 2018 | C4: https://resources.mlstatic.com/classifieds_accounts/MLC_real_estate_agency/210460829_vip_v2.JPG | D4: UF 7.200 a 34.200 | E4: https://www.portalinmobiliario.com/static_assets/landing/campana/corredores/img/verde.svg | F4: 1 | G4: 10 | H4: =+IF(G4>=100,"7.Mayor a 100 P",+IF(G4>=70,"6.Mayor a 70 P",+IF(G4>=40,"5.Mayor a 40 P",+IF(G4>=20,"4.Mayor a 20 P",+IF(G4>=10,"3.Mayor a 10 P",+IF(G4<10,"2.Menor a 10 P",+IF(G4=0,"1.Sin Propiedades","Revsar"))))))) -> 3.Mayor a 10 P | K4: Etiquetas de fila | L4: Cuenta de Tramos_Prom_Propiedades
A5: Sin Información | B5: 2025 | C5: https://www.portalinmobiliario.com/static_assets/landing/campana/corredores/img/casa_foto.jpg | D5: UF 2.293 a 3.822 | E5: https://www.portalinmobiliario.com/static_assets/landing/campana/corredores/img/verde.svg | F5: 1 | G5: 3 | H5: =+IF(G5>=100,"7.Mayor a 100 P",+IF(G5>=70,"6.Mayor a 70 P",+IF(G5>=40,"5.Mayor a 40 P",+IF(G5>=20,"4.Mayor a 20 P",+IF(G5>=10,"3.Mayor a 10 P",+IF(G5<10,"2.Menor a 10 P",+IF(G5=0,"1.Sin Propiedades","Revsar"))))))) -> 2.Menor a 10 P | K5: 2.Menor a 10 P | L5: 315
A6: Smf Propiedades | B6: 2018 | C6: https://resources.mlstatic.com/classifieds_accounts/MLC_real_estate_agency/330114471_vip.jpg | D6: UF 2.250 a 32.630 | E6: https://www.portalinmobiliario.com/static_assets/landing/campana/corredores/img/verde.svg | F6: 1 | G6: 4 | H6: =+IF(G6>=100,"7.Mayor a 100 P",+IF(G6>=70,"6.Mayor a 70 P",+IF(G6>=40,"5.Mayor a 40 P",+IF(G6>=20,"4.Mayor a 20 P",+IF(G6>=10,"3.Mayor a 10 P",+IF(G6<10,"2.Menor a 10 P",+IF(G6=0,"1.Sin Propiedades","Revsar"))))))) -> 2.Menor a 10 P | K6: 3.Mayor a 10 P | L6: 183
A7: Alma S.P.A | B7: 2019 | C7: https://resources.mlstatic.com/classifieds_accounts/MLC_real_estate_agency/466655639_vip.jpg | D7: UF 2.980 a 14.000 | E7: https://www.portalinmobiliario.com/static_assets/landing/campana/corredores/img/verde.svg | F7: 1 | G7: 7 | H7: =+IF(G7>=100,"7.Mayor a 100 P",+IF(G7>=70,"6.Mayor a 70 P",+IF(G7>=40,"5.Mayor a 40 P",+IF(G7>=20,"4.Mayor a 20 P",+IF(G7>=10,"3.Mayor a 10 P",+IF(G7<10,"2.Menor a 10 P",+IF(G7=0,"1.Sin Propiedades","Revsar"))))))) -> 2.Menor a 10 P | K7: 4.Mayor a 20 P | L7: 139
A8: Tips Propiedades | B8: 2018 | C8: https://http2.mlstatic.com/storage/vis-accounts/203086925_vip-b27631b9-ae08-4e9e-a7b8-80b37f4ce107.png | D8: UF 1.100 a 14.000 | E8: https://www.portalinmobiliario.com/static_assets/landing/campana/corredores/img/verde.svg | F8: 1 | G8: 25 | H8: =+IF(G8>=100,"7.Mayor a 100 P",+IF(G8>=70,"6.Mayor a 70 P",+IF(G8>=40,"5.Mayor a 40 P",+IF(G8>=20,"4.Mayor a 20 P",+IF(G8>=10,"3.Mayor a 10 P",+IF(G8<10,"2.Menor a 10 P",+IF(G8=0,"1.Sin Propiedades","Revsar"))))))) -> 4.Mayor a 20 P | K8: 5.Mayor a 40 P | L8: 84
A9: Scott Propiedades | B9: 2025 | C9: https://http2.mlstatic.com/storage/vis-accounts/1356336812_vip-ca9ab640-a28d-4913-b17a-c0e3c30b9ae1.jpg | D9: UF 2.550 a 24.000 | E9: https://www.portalinmobiliario.com/static_assets/landing/campana/corredores/img/verde.svg | F9: 1 | G9: 8 | H9: =+IF(G9>=100,"7.Mayor a 100 P",+IF(G9>=70,"6.Mayor a 70 P",+IF(G9>=40,"5.Mayor a 40 P",+IF(G9>=20,"4.Mayor a 20 P",+IF(G9>=10,"3.Mayor a 10 P",+IF(G9<10,"2.Menor a 10 P",+IF(G9=0,"1.Sin Propiedades","Revsar"))))))) -> 2.Menor a 10 P | K9: 6.Mayor a 70 P | L9: 38
A10: Ecosin Propiedades | B10: 2017 | C10: https://http2.mlstatic.com/storage/vis-accounts/281012386_vip-689e801d-fb88-45eb-bfaf-36baca034123.jpg | D10: UF 3.800 a 8.700 | E10: https://www.portalinmobiliario.com/static_assets/landing/campana/corredores/img/verde.svg | F10: 1 | G10: 5 | H10: =+IF(G10>=100,"7.Mayor a 100 P",+IF(G10>=70,"6.Mayor a 70 P",+IF(G10>=40,"5.Mayor a 40 P",+IF(G10>=20,"4.Mayor a 20 P",+IF(G10>=10,"3.Mayor a 10 P",+IF(G10<10,"2.Menor a 10 P",+IF(G10=0,"1.Sin Propiedades","Revsar"))))))) -> 2.Menor a 10 P | K10: 7.Mayor a 100 P | L10: 85
A11: Pamela Redard | B11: 2019 | C11: https://resources.mlstatic.com/classifieds_accounts/MLC_real_estate_agency/352544924_vip.jpg | D11: UF 3.900 a 8.197 | E11: https://www.portalinmobiliario.com/static_assets/landing/campana/corredores/img/verde.svg | F11: 1 | G11: 5 | H11: =+IF(G11>=100,"7.Mayor a 100 P",+IF(G11>=70,"6.Mayor a 70 P",+IF(G11>=40,"5.Mayor a 40 P",+IF(G11>=20,"4.Mayor a 20 P",+IF(G11>=10,"3.Mayor a 10 P",+IF(G11<10,"2.Menor a 10 P",+IF(G11=0,"1.Sin Propiedades","Revsar"))))))) -> 2.Menor a 10 P | K11: Total general | L11: 844
A12: Mauricio Reyes Aranda | B12: 2020 | C12: https://www.portalinmobiliario.com/static_assets/landing/campana/corredores/img/casa_foto.jpg | D12: UF 2.110 a 10.500 | E12: https://www.portalinmobiliario.com/static_assets/landing/campana/corredores/img/verde.svg | F12: 1 | G12: 10 | H12: =+IF(G12>=100,"7.Mayor a 100 P",+IF(G12>=70,"6.Mayor a 70 P",+IF(G12>=40,"5.Mayor a 40 P",+IF(G12>=20,"4.Mayor a 20 P",+IF(G12>=10,"3.Mayor a 10 P",+IF(G12<10,"2.Menor a 10 P",+IF(G12=0,"1.Sin Propiedades","Revsar"))))))) -> 3.Mayor a 10 P
A13: Horizontal Propiedades | B13: 2020 | C13: https://resources.mlstatic.com/classifieds_accounts/MLC_real_estate_agency/580020941_vip.jpg | D13: UF 3.364 a 28.000 | E13: https://www.portalinmobiliario.com/static_assets/landing/campana/corredores/img/verde.svg | F13: 1 | G13: 7 | H13: =+IF(G13>=100,"7.Mayor a 100 P",+IF(G13>=70,"6.Mayor a 70 P",+IF(G13>=40,"5.Mayor a 40 P",+IF(G13>=20,"4.Mayor a 20 P",+IF(G13>=10,"3.Mayor a 10 P",+IF(G13<10,"2.Menor a 10 P",+IF(G13=0,"1.Sin Propiedades","Revsar"))))))) -> 2.Menor a 10 P
A14: Jacob Propiedades | B14: 2021 | C14: https://http2.mlstatic.com/storage/vis-accounts/777380068_vip-27ef33cc-3cbd-4a8f-85a4-dd555f56d401.jpg | D14: UF 1.274 a 139.000 | E14: https://www.portalinmobiliario.com/static_assets/landing/campana/corredores/img/verde.svg | F14: 0.97802198 | G14: 37 | H14: =+IF(G14>=100,"7.Mayor a 100 P",+IF(G14>=70,"6.Mayor a 70 P",+IF(G14>=40,"5.Mayor a 40 P",+IF(G14>=20,"4.Mayor a 20 P",+IF(G14>=10,"3.Mayor a 10 P",+IF(G14<10,"2.Menor a 10 P",+IF(G14=0,"1.Sin Propiedades","Revsar"))))))) -> 4.Mayor a 20 P
A15: Coeficiente Propiedades | B15: 2020 | C15: https://resources.mlstatic.com/classifieds_accounts/MLC_real_estate_agency/632327052_vip.jpg | D15: UF 2.300 a 49.900 | E15: https://www.portalinmobiliario.com/static_assets/landing/campana/corredores/img/verde.svg | F15: 0.97802198 | G15: 42 | H15: =+IF(G15>=100,"7.Mayor a 100 P",+IF(G15>=70,"6.Mayor a 70 P",+IF(G15>=40,"5.Mayor a 40 P",+IF(G15>=20,"4.Mayor a 20 P",+IF(G15>=10,"3.Mayor a 10 P",+IF(G15<10,"2.Menor a 10 P",+IF(G15=0,"1.Sin Propiedades","Revsar"))))))) -> 5.Mayor a 40 P
A16: Francisco Vial Propiedades Procasa | B16: 2022 | C16: https://www.portalinmobiliario.com/static_assets/landing/campana/corredores/img/casa_foto.jpg | D16: UF 1.200 a 45.000 | E16: https://www.portalinmobiliario.com/static_assets/landing/campana/corredores/img/verde.svg | F16: 0.96703297 | G16: 96 | H16: =+IF(G16>=100,"7.Mayor a 100 P",+IF(G16>=70,"6.Mayor a 70 P",+IF(G16>=40,"5.Mayor a 40 P",+IF(G16>=20,"4.Mayor a 20 P",+IF(G16>=10,"3.Mayor a 10 P",+IF(G16<10,"2.Menor a 10 P",+IF(G16=0,"1.Sin Propiedades","Revsar"))))))) -> 6.Mayor a 70 P
A17: Marticorena Propiedades | B17: 2018 | C17: https://http2.mlstatic.com/storage/vis-accounts/188991960_vip-193f6525-a5f1-4bfc-8aa7-ab71ea3c4902.png | D17: UF 1.480 a 16.150 | E17: https://www.portalinmobiliario.com/static_assets/landing/campana/corredores/img/verde.svg | F17: 0.95604396 | G17: 28 | H17: =+IF(G17>=100,"7.Mayor a 100 P",+IF(G17>=70,"6.Mayor a 70 P",+IF(G17>=40,"5.Mayor a 40 P",+IF(G17>=20,"4.Mayor a 20 P",+IF(G17>=10,"3.Mayor a 10 P",+IF(G17<10,"2.Menor a 10 P",+IF(G17=0,"1.Sin Propiedades","Revsar"))))))) -> 4.Mayor a 20 P
A18: Valle La Dehesa Propiedades | B18: 2019 | C18: https://http2.mlstatic.com/storage/vis-accounts/302982195_vip-3650097e-4086-41f3-9aaa-9e8e835c8464.jpg | D18: UF 7.540 a 23.900 | E18: https://www.portalinmobiliario.com/static_assets/landing/campana/corredores/img/verde.svg | F18: 0.95604396 | G18: 4 | H18: =+IF(G18>=100,"7.Mayor a 100 P",+IF(G18>=70,"6.Mayor a 70 P",+IF(G18>=40,"5.Mayor a 40 P",+IF(G18>=20,"4.Mayor a 20 P",+IF(G18>=10,"3.Mayor a 10 P",+IF(G18<10,"2.Menor a 10 P",+IF(G18=0,"1.Sin Propiedades","Revsar"))))))) -> 2.Menor a 10 P
A19: Javier Cerpa Propiedades | B19: 2018 | C19: https://http2.mlstatic.com/storage/vis-accounts/330122684_vip-bd6700d5-a06a-4b16-8b65-f3c94aa82695.jpg | D19: UF 1.529 a 98.000 | E19: https://www.portalinmobiliario.com/static_assets/landing/campana/corredores/img/verde.svg | F19: 0.94505495 | G19: 279 | H19: =+IF(G19>=100,"7.Mayor a 100 P",+IF(G19>=70,"6.Mayor a 70 P",+IF(G19>=40,"5.Mayor a 40 P",+IF(G19>=20,"4.Mayor a 20 P",+IF(G19>=10,"3.Mayor a 10 P",+IF(G19<10,"2.Menor a 10 P",+IF(G19=0,"1.Sin Propiedades","Revsar"))))))) -> 7.Mayor a 100 P
A20: Mi Sitio Propiedades Spa | B20: 2021 | C20: https://http2.mlstatic.com/storage/vis-accounts/755052371_vip-60ecdb77-8b09-4dc7-a54a-9f64951f9909.png | D20: UF 1.650 a 14.500 | E20: https://www.portalinmobiliario.com/static_assets/landing/campana/corredores/img/verde.svg | F20: 0.94505495 | G20: 15 | H20: =+IF(G20>=100,"7.Mayor a 100 P",+IF(G20>=70,"6.Mayor a 70 P",+IF(G20>=40,"5.Mayor a 40 P",+IF(G20>=20,"4.Mayor a 20 P",+IF(G20>=10,"3.Mayor a 10 P",+IF(G20<10,"2.Menor a 10 P",+IF(G20=0,"1.Sin Propiedades","Revsar"))))))) -> 3.Mayor a 10 P
A21: Corvalan Asociados Spa | B21: 2022 | C21: https://http2.mlstatic.com/storage/vis-accounts/720638632_vip-c1437183-dfa5-49c9-b326-26bdc180b7f5.png | D21: UF 1.274 a 8.154 | E21: https://www.portalinmobiliario.com/static_assets/landing/campana/corredores/img/verde.svg | F21: 0.94505495 | G21: 12 | H21: =+IF(G21>=100,"7.Mayor a 100 P",+IF(G21>=70,"6.Mayor a 70 P",+IF(G21>=40,"5.Mayor a 40 P",+IF(G21>=20,"4.Mayor a 20 P",+IF(G21>=10,"3.Mayor a 10 P",+IF(G21<10,"2.Menor a 10 P",+IF(G21=0,"1.Sin Propiedades","Revsar"))))))) -> 3.Mayor a 10 P
A22: Dimensión Propiedades | B22: 2018 | C22: https://http2.mlstatic.com/storage/vis-accounts/267443517_vip-0a003a23-24e0-407f-bb57-cbda5e32fcb6.jpg | D22: UF 1.900 a 11.467 | E22: https://www.portalinmobiliario.com/static_assets/landing/campana/corredores/img/verde.svg | F22: 0.91208791 | G22: 7 | H22: =+IF(G22>=100,"7.Mayor a 100 P",+IF(G22>=70,"6.Mayor a 70 P",+IF(G22>=40,"5.Mayor a 40 P",+IF(G22>=20,"4.Mayor a 20 P",+IF(G22>=10,"3.Mayor a 10 P",+IF(G22<10,"2.Menor a 10 P",+IF(G22=0,"1.Sin Propiedades","Revsar"))))))) -> 2.Menor a 10 P
A23: Altaa.Cl | B23: 2019 | C23: https://www.portalinmobiliario.com/static_assets/landing/campana/corredores/img/casa_foto.jpg | D23: UF 7.350 a 15.500 | E23: https://www.portalinmobiliario.com/static_assets/landing/campana/corredores/img/verde.svg | F23: 0.91208791 | G23: 5 | H23: =+IF(G23>=100,"7.Mayor a 100 P",+IF(G23>=70,"6.Mayor a 70 P",+IF(G23>=40,"5.Mayor a 40 P",+IF(G23>=20,"4.Mayor a 20 P",+IF(G23>=10,"3.Mayor a 10 P",+IF(G23<10,"2.Menor a 10 P",+IF(G23=0,"1.Sin Propiedades","Revsar"))))))) -> 2.Menor a 10 P
... A845: Dedica Propiedades Limitada | B845: 2019 | C845: https://http2.mlstatic.com/storage/vis-accounts/315340024_vip-a9aa3a41-fa23-48df-843d-b23b42e51a87.png | D845: UF 1.700 a 11.530 | E845: https://www.portalinmobiliario.com/static_assets/landing/campana/corredores/img/gris.svg | F845: 0 | G845: 7 | H845: =+IF(G845>=100,"7.Mayor a 100 P",+IF(G845>=70,"6.Mayor a 70 P",+IF(G845>=40,"5.Mayor a 40 P",+IF(G845>=20,"4.Mayor a 20 P",+IF(G845>=10,"3.Mayor a 10 P",+IF(G845<10,"2.Menor a 10 P",+IF(G845=0,"1.Sin Propiedades","Revsar"))))))) -> 2.Menor a 10 P

Sheet Hoja4

Sheet Poblacion_x_Comuna
A1: Key1 | B1: Región | C1: Unidad territorial | D1: Variable | E1: 2024 ini | F1: punto | G1: 2024 Fin
A2: =+C2&D2 -> Chile Hombre | B2: Total Chile | C2: Chile | D2: Hombre | E2: 9910500.0 | F2: =+FIND(".",E2) -> 9 | G2: =+LEFT(E2,(F2-1))*1 -> 9910500
A3: =+C3&D3 -> Chile Mujer | B3: Total Chile | C3: Chile | D3: Mujer | E3: 10175877.0 | F3: =+FIND(".",E3) -> 10 | G3: =+LEFT(E3,(F3-1))*1 -> 10175877
A4: =+C4&D4 -> Chile Población total | B4: Total Chile | C4: Chile | D4: Población total | E4: 20086377.0 | F4: =+FIND(".",E4) -> 10 | G4: =+LEFT(E4,(F4-1))*1 -> 20086377
A5: =+C5&D5 -> Chile Población de 0 a 14 años | B5: Total Chile | C5: Chile | D5: Población de 0 a 14 años | E5: 3698025.0 | F5: =+FIND(".",E5) -> 9 | G5: =+LEFT(E5,(F5-1))*1 -> 3698025
A6: =+C6&D6 -> Chile Población de 15 a 64 años | B6: Total Chile | C6: Chile | D6: Población de 15 a 64 años | E6: 13619165.0 | F6: =+FIND(".",E6) -> 10 | G6: =+LEFT(E6,(F6-1))*1 -> 13619165
A7: =+C7&D7 -> Chile Población de 65 años o mas | B7: Total Chile | C7: Chile | D7: Población de 65 años o mas | E7: 2769187.0 | F7: =+FIND(".",E7) -> 9 | G7: =+LEFT(E7,(F7-1))*1 -> 2769187
A8: =+C8&D8 -> Región De Arica Y Parinacota Hombre | B8: Región De Arica Y Parinacota | C8: Región De Arica Y Parinacota | D8: Hombre | E8: 132125.0 | F8: =+FIND(".",E8) -> 8 | G8: =+LEFT(E8,(F8-1))*1 -> 132125
A9: =+C9&D9 -> Región De Arica Y Parinacota Mujer | B9: Región De Arica Y Parinacota | C9: Región De Arica Y Parinacota | D9: Mujer | E9: 129654.0 | F9: =+FIND(".",E9) -> 8 | G9: =+LEFT(E9,(F9-1))*1 -> 129654
A10: =+C10&D10 -> Región De Arica Y Parinacota Población total | B10: Región De Arica Y Parinacota | C10: Región De Arica Y Parinacota | D10: Población total | E10: 261779.0 | F10: =+FIND(".",E10) -> 8 | G10: =+LEFT(E10,(F10-1))*1 -> 261779
A11: =+C11&D11 -> Región De Arica Y Parinacota Población de 0 a 14 años | B11: Región De Arica Y Parinacota | C11: Región De Arica Y Parinacota | D11: Población de 0 a 14 años | E11: 51543.0 | F11: =+FIND(".",E11) -> 7 | G11: =+LEFT(E11,(F11-1))*1 -> 51543
A12: =+C12&D12 -> Región De Arica Y Parinacota Población de 15 a 64 años | B12: Región De Arica Y Parinacota | C12: Región De Arica Y Parinacota | D12: Población de 15 a 64 años | E12: 176644.0 | F12: =+FIND(".",E12) -> 8 | G12: =+LEFT(E12,(F12-1))*1 -> 176644
A13: =+C13&D13 -> Región De Arica Y Parinacota Población de 65 años o mas | B13: Región De Arica Y Parinacota | C13: Región De Arica Y Parinacota | D13: Población de 65 años o mas | E13: 33592.0 | F13: =+FIND(".",E13) -> 7 | G13: =+LEFT(E13,(F13-1))*1 -> 33592
... A2179: =+C2179&D2179 -> Antártica Población de 65 años o mas | B2179: Región De Magallanes Y De La Antártica Chilena | C2179: Antártica | D2179: Población de 65 años o mas | E2179: 0.0 | F2179: =+FIND(".",E2179) -> 3 | G2179: =+LEFT(E2179,(F2179-1))*1 -> 0

Sheet Poblacion_x_Región
A1: Unidad territorial | B1: Variable | C1: 2024 | D1: punto | E1: 2024 Fin | G1: Unidad territorial | H1: Región Metropolitana De Santiago
A2: Región De Arica Y Parinacota | B2: Hombre | C2: 132125.0 | D2: =+FIND(".",C2) -> 8 | E2: =+LEFT(C2,(D2-1))*1 -> 132125
A3: Región De Arica Y Parinacota | B3: Mujer | C3: 129654.0 | D3: =+FIND(".",C3) -> 8 | E3: =+LEFT(C3,(D3-1))*1 -> 129654 | G3: Etiquetas de fila | H3: 2024 Fin
A4: Región De Arica Y Parinacota | B4: Población total | C4: 261779.0 | D4: =+FIND(".",C4) -> 8 | E4: =+LEFT(C4,(D4-1))*1 -> 261779 | G4: Hombre | H4: 4166844
A5: Región De Arica Y Parinacota | B5: Población de 0 a 14 años | C5: 51543.0 | D5: =+FIND(".",C5) -> 7 | E5: =+LEFT(C5,(D5-1))*1 -> 51543 | G5: Mujer | H5: 4253885
A6: Región De Arica Y Parinacota | B6: Población de 15 a 64 años | C6: 176644.0 | D6: =+FIND(".",C6) -> 8 | E6: =+LEFT(C6,(D6-1))*1 -> 176644 | G6: Población de 0 a 14 años | H6: 1527250
A7: Región De Arica Y Parinacota | B7: Población de 65 años o mas | C7: 33592.0 | D7: =+FIND(".",C7) -> 7 | E7: =+LEFT(C7,(D7-1))*1 -> 33592 | G7: Población de 15 a 64 años | H7: 5839488
A8: Región De Tarapacá | B8: Hombre | C8: 204628.0 | D8: =+FIND(".",C8) -> 8 | E8: =+LEFT(C8,(D8-1))*1 -> 204628 | G8: Población de 65 años o mas | H8: 1053991
A9: Región De Tarapacá | B9: Mujer | C9: 201659.0 | D9: =+FIND(".",C9) -> 8 | E9: =+LEFT(C9,(D9-1))*1 -> 201659 | G9: Población total | H9: 8420729
A10: Región De Tarapacá | B10: Población total | C10: 406287.0 | D10: =+FIND(".",C10) -> 8 | E10: =+LEFT(C10,(D10-1))*1 -> 406287 | G10: Total general | H10: 25262187
A11: Región De Tarapacá | B11: Población de 0 a 14 años | C11: 89422.0 | D11: =+FIND(".",C11) -> 7 | E11: =+LEFT(C11,(D11-1))*1 -> 89422
A12: Región De Tarapacá | B12: Población de 15 a 64 años | C12: 278679.0 | D12: =+FIND(".",C12) -> 8 | E12: =+LEFT(C12,(D12-1))*1 -> 278679
A13: Región De Tarapacá | B13: Población de 65 años o mas | C13: 38186.0 | D13: =+FIND(".",C13) -> 7 | E13: =+LEFT(C13,(D13-1))*1 -> 38186
A14: Región De Antofagasta | B14: Hombre | C14: 361009.0 | D14: =+FIND(".",C14) -> 8 | E14: =+LEFT(C14,(D14-1))*1 -> 361009
A15: Región De Antofagasta | B15: Mujer | C15: 357223.0 | D15: =+FIND(".",C15) -> 8 | E15: =+LEFT(C15,(D15-1))*1 -> 357223
A16: Región De Antofagasta | B16: Población total | C16: 718232.0 | D16: =+FIND(".",C16) -> 8 | E16: =+LEFT(C16,(D16-1))*1 -> 718232
A17: Región De Antofagasta | B17: Población de 0 a 14 años | C17: 143591.0 | D17: =+FIND(".",C17) -> 8 | E17: =+LEFT(C17,(D17-1))*1 -> 143591
A18: Región De Antofagasta | B18: Población de 15 a 64 años | C18: 510597.0 | D18: =+FIND(".",C18) -> 8 | E18: =+LEFT(C18,(D18-1))*1 -> 510597
A19: Región De Antofagasta | B19: Población de 65 años o mas | C19: 64044.0 | D19: =+FIND(".",C19) -> 7 | E19: =+LEFT(C19,(D19-1))*1 -> 64044
A20: Región De Atacama | B20: Hombre | C20: 161331.0 | D20: =+FIND(".",C20) -> 8 | E20: =+LEFT(C20,(D20-1))*1 -> 161331
A21: Región De Atacama | B21: Mujer | C21: 158661.0 | D21: =+FIND(".",C21) -> 8 | E21: =+LEFT(C21,(D21-1))*1 -> 158661
A22: Región De Atacama | B22: Población total | C22: 319992.0 | D22: =+FIND(".",C22) -> 8 | E22: =+LEFT(C22,(D22-1))*1 -> 319992
... A97: Región De Magallanes Y De La Antártica Chilena | B97: Población de 65 años o mas | C97: 26154.0 | D97: =+FIND(".",C97) -> 7 | E97: =+LEFT(C97,(D97-1))*1 -> 26154

Sheet TD_Pob_x_Comuna
A1: Región | B1: Región Metropolitana De Santiago
A3: Suma de 2024 Fin | B3: .
A4: Comuna | B4: Hombre | C4: Mujer | D4: Población de 0 a 14 años | E4: Población de 15 a 64 años | F4: Población de 65 años o mas | G4: Población total
A5: Región Metropolitana De Santiago | B5: 4166844 | C5: 4253885 | D5: 1527250 | E5: 5839488 | F5: 1053991 | G5: 8420729
A6: Puente Alto | B6: 329119 | C6: 338785 | D6: 136594 | E6: 470295 | F6: 61015 | G6: 667904
A7: Maipú | B7: 288528 | C7: 298284 | D7: 106956 | E7: 414462 | F7: 65394 | G7: 586812
A8: Santiago | B8: 274718 | C8: 269670 | D8: 61416 | E8: 434119 | F8: 48853 | G8: 544388
A9: La Florida | B9: 200711 | C9: 206586 | D9: 69328 | E9: 276825 | F9: 61144 | G9: 407297
A10: San Bernardo | B10: 172517 | C10: 176123 | D10: 74467 | E10: 238131 | F10: 36042 | G10: 348640
A11: Las Condes | B11: 167662 | C11: 175970 | D11: 49282 | E11: 232604 | F11: 61746 | G11: 343632
A12: Quilicura | B12: 137276 | C12: 138468 | D12: 59689 | E12: 198070 | F12: 17985 | G12: 275744
A13: Peñalolén | B13: 134721 | C13: 138192 | D13: 52264 | E13: 187524 | F13: 33125 | G13: 272913
A14: Ñuñoa | B14: 130692 | C14: 136214 | D14: 36355 | E14: 186803 | F14: 43748 | G14: 266906
A15: Pudahuel | B15: 129048 | C15: 132548 | D15: 51975 | E15: 183162 | F15: 26459 | G15: 261596
A16: Estación Central | B16: 111738 | C16: 110163 | D16: 34778 | E16: 157298 | F16: 29825 | G16: 221901
... A58: Total general | B58: 8333688 | C58: 8507770 | D58: 3054500 | E58: 11678976 | F58: 2107982 | G58: 16841458

Sheet P&G (2)
A1: Elija Comuna | C1: Hombre | D1: Mujer | E1: Población de 0 a 14 años | F1: Población de 15 a 64 años | G1: Población de 65 años o mas | H1: Población total
A2: =+'P&G_Agente_Inmobiliario'!A2 -> 0 | C2: =_xlfn.XLOOKUP(+CONCATENATE($A$2,C1),Poblacion_x_Comuna!$A:$A,Poblacion_x_Comuna!$G:$G) -> #N/A | D2: =_xlfn.XLOOKUP(+CONCATENATE($A$2,D1),Poblacion_x_Comuna!$A:$A,Poblacion_x_Comuna!$G:$G) -> #N/A | E2: =_xlfn.XLOOKUP(+CONCATENATE($A$2,E1),Poblacion_x_Comuna!$A:$A,Poblacion_x_Comuna!$G:$G) -> #N/A | F2: =_xlfn.XLOOKUP(+CONCATENATE($A$2,F1),Poblacion_x_Comuna!$A:$A,Poblacion_x_Comuna!$G:$G) -> #N/A | G2: =_xlfn.XLOOKUP(+CONCATENATE($A$2,G1),Poblacion_x_Comuna!$A:$A,Poblacion_x_Comuna!$G:$G) -> #N/A | H2: =_xlfn.XLOOKUP(+CONCATENATE($A$2,H1),Poblacion_x_Comuna!$A:$A,Poblacion_x_Comuna!$G:$G) -> #N/A
A4: MODELO1 | B4: Mes 0 | C4: Mes 1 | D4: Mes 2 | E4: Mes 3 | F4: Mes 4 | G4: Mes 5 | H4: Mes 6 | I4: Mes 7 | J4: Mes 8 | K4: Mes 9 | L4: Mes 10 | M4: Mes 11 | N4: Mes 12 | O4: YTD | P4: PROM YEAR
A5: Confort por Paquete | C5: 2 | D5: 16 | E5: 16 | F5: 16 | G5: 16 | H5: 16 | I5: 16 | J5: 16 | K5: 16 | L5: 16 | M5: 16 | N5: 16 | O5: =+SUM(C5:N5) -> 178 | P5: =+O5/12 -> 14.833333
A6: Cantidad de paquetes | C6: 300 | D6: 300 | E6: 300 | F6: 300 | G6: 300 | H6: 300 | I6: 300 | J6: 300 | K6: 300 | L6: 300 | M6: 300 | N6: 300 | O6: =+SUM(C6:N6) -> 3600 | P6: =+O6/12 -> 300
A7: Clientes | C7: =+H2*3% -> #N/A | D7: =+C7*1.01 -> #N/A | E7: =+D7*1.01 -> #N/A | F7: =+E7*1.01 -> #N/A | G7: =+F7*1.01 -> #N/A | H7: =+G7*1.01 -> #N/A | I7: =+H7*1.01 -> #N/A | J7: =+I7*1.01 -> #N/A | K7: =+J7*1.01 -> #N/A | ... N7: =+M7*1.01 -> #N/A | O7: =+SUM(C7:N7) -> #N/A | P7: =+O7/12 -> #N/A
A8: Costo por paquete | C8: 500 | D8: =+(C8/C5)*D5 -> 4000 | E8: =+(D8/D5)*E5 -> 4000 | F8: =+(E8/E5)*F5 -> 4000 | G8: =+(F8/F5)*G5 -> 4000 | H8: =+(G8/G5)*H5 -> 4000 | I8: =+(H8/H5)*I5 -> 4000 | J8: =+(I8/I5)*J5 -> 4000 | K8: =+(J8/J5)*K5 -> 4000 | ... N8: =+(M8/M5)*N5 -> 4000
A9: Venta por paquete | C9: =+C8/0.5 -> 1000 | D9: =+(C9/C5)*D5 -> 8000 | E9: =+(D9/D5)*E5 -> 8000 | F9: =+(E9/E5)*F5 -> 8000 | G9: =+(F9/F5)*G5 -> 8000 | H9: =+(G9/G5)*H5 -> 8000 | I9: =+(H9/H5)*I5 -> 8000 | J9: =+(I9/I5)*J5 -> 8000 | K9: =+(J9/J5)*K5 -> 8000 | ... N9: =+(M9/M5)*N5 -> 8000
A10: Costo por unidad | C10: =+C8/C5 -> 250 | D10: 500 | E10: 500 | F10: 500 | G10: 500 | H10: 500 | I10: 500 | J10: 500 | K10: 500 | L10: 500 | M10: 500 | N10: 500
A11: Venta por unidad | C11: =+C9/C5 -> 500 | D11: 990 | E11: 990 | F11: 990 | G11: 990 | H11: 990 | I11: 990 | J11: 990 | K11: 990 | L11: 990 | M11: 990 | N11: 990
A12: Tasa de Clientes | B12: 0 | C12: 0.1 | D12: =+C12+0.07 -> 0.17 | E12: =+D12+0.07 -> 0.24 | F12: =+E12+0.07 -> 0.31 | G12: =+F12+0.07 -> 0.38 | H12: =+G12+0.07 -> 0.45 | I12: =+H12+0.07 -> 0.52 | J12: =+I12+0.07 -> 0.59 | K12: =+J12+0.07 -> 0.66 | ... N12: =+M12+0.07 -> 0.87
A13: Churn Clientes | B13: 0 | D13: 0.03 | E13: 0.03 | F13: 0.03 | G13: 0.03 | H13: 0.03 | I13: 0.03 | J13: 0.03 | K13: 0.03 | L13: 0.03 | M13: 0.03 | N13: 0.03
A14: Paquetes por cliente | B14: 1 | C14: 1 | D14: 1 | E14: 1 | F14: 1 | G14: 1 | H14: 1 | I14: 1 | J14: 1 | K14: 1 | L14: 1 | M14: 1 | N14: 1
A15: Clientes | B15: =+$C$7*B12*B14 -> #N/A | C15: =+C7*C12 -> #N/A | D15: =+D7*D12*(1-D13) -> #N/A | E15: =+E7*E12*(1-E13) -> #N/A | F15: =+F7*F12*(1-F13) -> #N/A | G15: =+G7*G12*(1-G13) -> #N/A | H15: =+H7*H12*(1-H13) -> #N/A | I15: =+I7*I12*(1-I13) -> #N/A | J15: =+J7*J12*(1-J13) -> #N/A | K15: =+K7*K12*(1-K13) -> #N/A | ... N15: =+N7*N12*(1-N13) -> #N/A
A16: Ingresos | B16: =+$C$9*B14*0 -> 0 | C16: =+C9*C15*C14 -> #N/A | D16: =+D9*D15*D14 -> #N/A | E16: =+E9*E15*E14 -> #N/A | F16: =+F9*F15*F14 -> #N/A | G16: =+G9*G15*G14 -> #N/A | H16: =+H9*H15*H14 -> #N/A | I16: =+I9*I15*I14 -> #N/A | J16: =+J9*J15*J14 -> #N/A | ... N16: =+N9*N15*N14 -> #N/A | O16: =+SUM(B16:N16) -> #N/A | P16: =+O16/12 -> #N/A
A18: Costos Productos | B18: =+$C$33*C8*-1 -> #N/A | C18: =+C8*C15*C14*-1 -> #N/A | D18: =+D8*D15*D14*-1 -> #N/A | E18: =+E8*E15*E14*-1 -> #N/A | F18: =+F8*F15*F14*-1 -> #N/A | G18: =+G8*G15*G14*-1 -> #N/A | H18: =+H8*H15*H14*-1 -> #N/A | I18: =+I8*I15*I14*-1 -> #N/A | J18: =+J8*J15*J14*-1 -> #N/A | ... N18: =+N8*N15*N14*-1 -> #N/A | O18: =+SUM(B18:N18) -> #N/A | P18: =+O18/12 -> #N/A
A19: Costos Directos | C19: =1500000*-1 -> -1500000 | D19: =1500000*-1 -> -1500000 | E19: =1500000*-1 -> -1500000 | F19: =1500000*-1 -> -1500000 | G19: =1500000*-1 -> -1500000 | H19: =1500000*-1 -> -1500000 | I19: =2500000*-1 -> -2500000 | J19: =2500000*-1 -> -2500000 | K19: =2500000*-1 -> -2500000 | L19: =2500000*-1 -> -2500000 | M19: =2500000*-1 -> -2500000 | N19: =2500000*-1 -> -2500000 | O19: =+SUM(B19:N19) -> -24000000 | P19: =+O19/12 -> -2000000
A20: Costos MKT | B20: =2000000*-1 -> -2000000 | C20: =2000000*-1 -> -2000000 | D20: =2000000*-1 -> -2000000 | E20: =2000000*-1 -> -2000000 | F20: =2000000*-1 -> -2000000 | G20: =2000000*-1 -> -2000000 | H20: =2000000*-1 -> -2000000 | I20: =2000000*-1 -> -2000000 | ... N20: =2000000*-1 -> -2000000 | O20: =+SUM(B20:N20) -> -26000000 | P20: =+O20/12 -> -2166666.7
A21: Costos Despachos | C21: =+C15*990*-1 -> #N/A | D21: =+D15*990*-1 -> #N/A | E21: =+E15*990*-1 -> #N/A | F21: =+F15*990*-1 -> #N/A | G21: =+G15*990*-1 -> #N/A | H21: =+H15*990*-1 -> #N/A | I21: =+I15*990*-1 -> #N/A | J21: =+J15*990*-1 -> #N/A | ... N21: =+N15*990*-1 -> #N/A | O21: =+SUM(B21:N21) -> #N/A | P21: =+O21/12 -> #N/A
A22: TT Costos | B22: =B18+B19+B20+B21 -> #N/A | C22: =C18+C19+C20+C21 -> #N/A | D22: =D18+D19+D20+D21 -> #N/A | E22: =E18+E19+E20+E21 -> #N/A | F22: =F18+F19+F20+F21 -> #N/A | G22: =G18+G19+G20+G21 -> #N/A | H22: =H18+H19+H20+H21 -> #N/A | I22: =I18+I19+I20+I21 -> #N/A | ... N22: =N18+N19+N20+N21 -> #N/A | O22: =+SUM(B22:N22) -> #N/A | P22: =+O22/12 -> #N/A
A23: Costos Acumulados | B23: =+B22 -> #N/A | C23: =+B23+C22 -> #N/A | D23: =+C23+D22 -> #N/A | E23: =+D23+E22 -> #N/A | F23: =+E23+F22 -> #N/A | G23: =+F23+G22 -> #N/A | H23: =+G23+H22 -> #N/A | I23: =+H23+I22 -> #N/A | J23: =+I23+J22 -> #N/A | ... N23: =+M23+N22 -> #N/A
A25: MB $ | C25: =+C16+C22 -> #N/A | D25: =+D16+D22 -> #N/A | E25: =+E16+E22 -> #N/A | F25: =+F16+F22 -> #N/A | G25: =+G16+G22 -> #N/A | H25: =+H16+H22 -> #N/A | I25: =+I16+I22 -> #N/A | J25: =+J16+J22 -> #N/A | ... O25: =+O16+O22 -> #N/A | P25: =+O25/12 -> #N/A
A26: MB % | C26: =+C25/C16 -> #N/A | D26: =+D25/D16 -> #N/A | E26: =+E25/E16 -> #N/A | F26: =+F25/F16 -> #N/A | G26: =+G25/G16 -> #N/A | H26: =+H25/H16 -> #N/A | I26: =+I25/I16 -> #N/A | J26: =+J25/J16 -> #N/A | ... P26: =+P25/P16 -> #N/A
A27: MB Acumulado $ | C27: =+SUM($B$16:C16)+C23 -> #N/A | D27: =+SUM($B$16:D16)+D23 -> #N/A | E27: =+SUM($B$16:E16)+E23 -> #N/A | F27: =+SUM($B$16:F16)+F23 -> #N/A | G27: =+SUM($B$16:G16)+G23 -> #N/A | H27: =+SUM($B$16:H16)+H23 -> #N/A | I27: =+SUM($B$16:I16)+I23 -> #N/A | J27: =+SUM($B$16:J16)+J23 -> #N/A | ... N27: =+SUM($B$16:N16)+N23 -> #N/A
A28: MB Acumulado % | C28: =+C27/+SUM($B$16:C16) -> #N/A | D28: =+D27/+SUM($B$16:D16) -> #N/A | E28: =+E27/+SUM($B$16:E16) -> #N/A | F28: =+F27/+SUM($B$16:F16) -> #N/A | G28: =+G27/+SUM($B$16:G16) -> #N/A | H28: =+H27/+SUM($B$16:H16) -> #N/A | I28: =+I27/+SUM($B$16:I16) -> #N/A | J28: =+J27/+SUM($B$16:J16) -> #N/A | ... N28: =+N27/+SUM($B$16:N16) -> #N/A
A30: MODELO2 | B30: Mes 0 | C30: Mes 1 | D30: Mes 2 | E30: Mes 3 | F30: Mes 4 | G30: Mes 5 | H30: Mes 6 | I30: Mes 7 | J30: Mes 8 | K30: Mes 9 | L30: Mes 10 | M30: Mes 11 | N30: Mes 12 | O30: YTD | P30: PROM YEAR
A31: Confort por Paquete | C31: 4 | D31: 24 | E31: 24 | F31: 24 | G31: 24 | H31: 24 | I31: 24 | J31: 24 | K31: 24 | L31: 24 | M31: 24 | N31: 24 | O31: =+SUM(C31:N31) -> 268 | P31: =+O31/12 -> 22.333333
A32: Cantidad de paquetes | C32: 300 | D32: 300 | E32: 300 | F32: 300 | G32: 300 | H32: 300 | I32: 300 | J32: 300 | K32: 300 | L32: 300 | M32: 300 | N32: 300 | O32: =+SUM(C32:N32) -> 3600 | P32: =+O32/12 -> 300
A33: Clientes | C33: =+C7 -> #N/A | D33: =+C33*1.01 -> #N/A | E33: =+D33*1.01 -> #N/A | F33: =+E33*1.01 -> #N/A | G33: =+F33*1.01 -> #N/A | H33: =+G33*1.01 -> #N/A | I33: =+H33*1.01 -> #N/A | J33: =+I33*1.01 -> #N/A | K33: =+J33*1.01 -> #N/A | ... N33: =+M33*1.01 -> #N/A | O33: =+SUM(C33:N33) -> #N/A | P33: =+O33/12 -> #N/A
A34: Costo por paquete | C34: =+C31*C10 -> 1000 | D34: =+(C34/C31)*D31 -> 6000 | E34: =+(D34/D31)*E31 -> 6000 | F34: =+(E34/E31)*F31 -> 6000 | G34: =+(F34/F31)*G31 -> 6000 | H34: =+(G34/G31)*H31 -> 6000 | I34: =+(H34/H31)*I31 -> 6000 | J34: =+(I34/I31)*J31 -> 6000 | K34: =+(J34/J31)*K31 -> 6000 | ... N34: =+(M34/M31)*N31 -> 6000
A35: Venta por paquete | C35: =+C34/0.5 -> 2000 | D35: =+(C35/C31)*D31 -> 12000 | E35: =+(D35/D31)*E31 -> 12000 | F35: =+(E35/E31)*F31 -> 12000 | G35: =+(F35/F31)*G31 -> 12000 | H35: =+(G35/G31)*H31 -> 12000 | I35: =+(H35/H31)*I31 -> 12000 | J35: =+(I35/I31)*J31 -> 12000 | K35: =+(J35/J31)*K31 -> 12000 | ... N35: =+(M35/M31)*N31 -> 12000
A36: Costo por unidad | C36: =+C34/C31 -> 250 | D36: =+(C34/C31)*D31/D31 -> 250 | E36: =+(D34/D31)*E31/E31 -> 250 | F36: =+(E34/E31)*F31/F31 -> 250 | G36: =+(F34/F31)*G31/G31 -> 250 | H36: =+(G34/G31)*H31/H31 -> 250 | I36: =+(H34/H31)*I31/I31 -> 250 | J36: =+(I34/I31)*J31/J31 -> 250 | K36: =+(J34/J31)*K31/K31 -> 250 | ... N36: =+(M34/M31)*N31/N31 -> 250 | O36: =+N36 -> 250 | P36: =+O36 -> 250
A37: Venta por unidad | C37: =+C35/C31 -> 500 | D37: =+(C35/C31)*D31/D31 -> 500 | E37: =+(D35/D31)*E31/E31 -> 500 | F37: =+(E35/E31)*F31/F31 -> 500 | G37: =+(F35/F31)*G31/G31 -> 500 | H37: =+(G35/G31)*H31/H31 -> 500 | I37: =+(H35/H31)*I31/I31 -> 500 | J37: =+(I35/I31)*J31/J31 -> 500 | K37: =+(J35/J31)*K31/K31 -> 500 | ... N37: =+(M35/M31)*N31/N31 -> 500 | O37: =+N37 -> 500 | P37: =+O37 -> 500
A38: Tasa Aumento de Clientes | B38: 0 | C38: 0.1 | D38: =+C38+0.07 -> 0.17 | E38: =+D38+0.07 -> 0.24 | F38: =+E38+0.07 -> 0.31 | G38: =+F38+0.07 -> 0.38 | H38: =+G38+0.07 -> 0.45 | I38: =+H38+0.07 -> 0.52 | J38: =+I38+0.07 -> 0.59 | K38: =+J38+0.07 -> 0.66 | ... N38: =+M38+0.07 -> 0.87
A39: Churn Clientes | B39: 0 | D39: 0.03 | E39: 0.03 | F39: 0.03 | G39: 0.03 | H39: 0.03 | I39: 0.03 | J39: 0.03 | K39: 0.03 | L39: 0.03 | M39: 0.03 | N39: 0.03
A40: Paquetes por cliente | B40: 1 | C40: 1 | D40: 1 | E40: 1 | F40: 1 | G40: 1 | H40: 1 | I40: 1 | J40: 1 | K40: 1 | L40: 1 | M40: 1 | N40: 1
A41: Clientes | B41: =+$C$7*B38*B40 -> #N/A | C41: =+C33*C38 -> #N/A | D41: =+D33*D38*(1-D39) -> #N/A | E41: =+E33*E38*(1-E39) -> #N/A | F41: =+F33*F38*(1-F39) -> #N/A | G41: =+G33*G38*(1-G39) -> #N/A | H41: =+H33*H38*(1-H39) -> #N/A | I41: =+I33*I38*(1-I39) -> #N/A | J41: =+J33*J38*(1-J39) -> #N/A | K41: =+K33*K38*(1-K39) -> #N/A | ... N41: =+N33*N38*(1-N39) -> #N/A
A42: Ingresos | B42: =+$C$9*B40*0 -> 0 | C42: =+C35*C41*C40 -> #N/A | D42: =+D35*D41*D40 -> #N/A | E42: =+E35*E41*E40 -> #N/A | F42: =+F35*F41*F40 -> #N/A | G42: =+G35*G41*G40 -> #N/A | H42: =+H35*H41*H40 -> #N/A | I42: =+I35*I41*I40 -> #N/A | J42: =+J35*J41*J40 -> #N/A | ... N42: =+N35*N41*N40 -> #N/A | O42: =+SUM(B42:N42) -> #N/A | P42: =+O42/12 -> #N/A
A44: Costos Productos | B44: =+$C$33*C34*-1 -> #N/A | C44: =+C34*C41*C40*-1 -> #N/A | D44: =+D34*D41*D40*-1 -> #N/A | E44: =+E34*E41*E40*-1 -> #N/A | F44: =+F34*F41*F40*-1 -> #N/A | G44: =+G34*G41*G40*-1 -> #N/A | H44: =+H34*H41*H40*-1 -> #N/A | I44: =+I34*I41*I40*-1 -> #N/A | J44: =+J34*J41*J40*-1 -> #N/A | ... N44: =+N34*N41*N40*-1 -> #N/A | O44: =+SUM(B44:N44) -> #N/A | P44: =+O44/12 -> #N/A
A45: Costos Directos | C45: =1500000*-1 -> -1500000 | D45: =1500000*-1 -> -1500000 | E45: =1500000*-1 -> -1500000 | F45: =1500000*-1 -> -1500000 | G45: =1500000*-1 -> -1500000 | H45: =1500000*-1 -> -1500000 | I45: =2500000*-1 -> -2500000 | J45: =2500000*-1 -> -2500000 | K45: =2500000*-1 -> -2500000 | L45: =2500000*-1 -> -2500000 | M45: =2500000*-1 -> -2500000 | N45: =2500000*-1 -> -2500000 | O45: =+SUM(B45:N45) -> -24000000 | P45: =+O45/12 -> -2000000
...

Sheet Hoja2
C2: Confort Elite
B3: Local | C3: Lider | D3: Tottus | E3: Unimarc | F3: Pica' Javi | G3: VeCo
B4: Mts | C4: 50 | D4: 50 | E4: 25 | F4: 50 | G4: 35
B5: Q Rollos | C5: 32 | D5: 4 | E5: 40 | F5: 32 | G5: 24
B6: Valor | C6: 18990 | D6: 3500 | E6: 17490 | F6: 17900 | G6: 12000
B7: Valor x rollo | C7: =+C6/C5 -> 593.4375 | D7: =+D6/D5 -> 875 | E7: =+E6/E5 -> 437.25 | F7: =+F6/F5 -> 559.375 | G7: =+G6/G5 -> 500
B8: Valor x Mt | C8: =+C7/C4 -> 11.86875 | D8: =+D7/D4 -> 17.5 | E8: =+E7/E4 -> 17.49 | F8: =+F7/F4 -> 11.1875 | G8: =+G7/G4 -> 14.285714
B10: Dim de la hoja | C10: 11.5 | D10: 11.5 | E10: 11.5 | F10: 11.5 | G10: 11.5
B11: Cms x rollo | C11: =+C4*100 -> 5000 | D11: =+D4*100 -> 5000 | E11: =+E4*100 -> 2500 | F11: =+F4*100 -> 5000 | G11: =+G4*100 -> 3500
B12: Q Hojas | C12: =+C11/C10 -> 434.78261 | D12: =+D11/D10 -> 434.78261 | E12: =+E11/E10 -> 217.3913 | F12: =+F11/F10 -> 434.78261 | G12: =+G11/G10 -> 304.34783
